<?xml version="1.0" ?>
<mujoco model="gait2354_newton">
  <compiler angle="radian" inertiafromgeom="auto" boundmass="0.01" boundinertia="0.01" discardvisual="false"/>
  <default>
    <joint limited="true" damping="0.05" armature="0.00001" stiffness="0"/>
    <geom rgba="0.8 0.6 .4 1" margin="0.001" density="1000"/>
  </default>
  <asset>
    <mesh name="bofoot" file="../mesh/gait2354/bofoot.stl" scale="1 1 1"/>
    <mesh name="femur_l" file="../mesh/gait2354/femur_l.stl" scale="1 1 1"/>
    <mesh name="femur_r" file="../mesh/gait2354/femur_r.stl" scale="1 1 1"/>
    <mesh name="fibula" file="../mesh/gait2354/fibula.stl" scale="1 1 1"/>
    <mesh name="foot" file="../mesh/gait2354/foot.stl" scale="1 1 1"/>
    <mesh name="hat_jaw" file="../mesh/gait2354/hat_jaw.stl" scale="1 1 1"/>
    <mesh name="hat_ribs" file="../mesh/gait2354/hat_ribs.stl" scale="1 1 1"/>
    <mesh name="hat_skull" file="../mesh/gait2354/hat_skull.stl" scale="1 1 1"/>
    <mesh name="hat_spine" file="../mesh/gait2354/hat_spine.stl" scale="1 1 1"/>
    <mesh name="l_bofoot" file="../mesh/gait2354/l_bofoot.stl" scale="1 1 1"/>
    <mesh name="l_fibula" file="../mesh/gait2354/l_fibula.stl" scale="1 1 1"/>
    <mesh name="l_foot" file="../mesh/gait2354/l_foot.stl" scale="1 1 1"/>
    <mesh name="l_pelvis" file="../mesh/gait2354/l_pelvis.stl" scale="1 1 1"/>
    <mesh name="l_talus" file="../mesh/gait2354/l_talus.stl" scale="1 1 1"/>
    <mesh name="pelvis" file="../mesh/gait2354/pelvis.stl" scale="1 1 1"/>
    <mesh name="sacrum" file="../mesh/gait2354/sacrum.stl" scale="1 1 1"/>
    <mesh name="talus" file="../mesh/gait2354/talus.stl" scale="1 1 1"/>
    <mesh name="tibia_l" file="../mesh/gait2354/tibia_l.stl" scale="1 1 1"/>
    <mesh name="tibia_r" file="../mesh/gait2354/tibia_r.stl" scale="1 1 1"/>
  </asset>
  <worldbody>
    <body name="pelvis" pos="0.0 -0.0 0.0">
      <inertial pos="0 0 0" mass="11.777" diaginertia="0.1028 0.0871 0.0579"/>
      <joint name="pelvis_tx" type="slide" axis="1.0 -0.0 0.0" range="-5.0 5.0"/>
      <joint name="pelvis_ty" type="slide" axis="0.0 -0.0 1.0" range="-1.0 2.0"/>
      <joint name="pelvis_tz" type="slide" axis="0.0 -1.0 0.0" range="-3.0 3.0"/>
      <joint name="pelvis_tilt" type="hinge" axis="0.0 -1.0 0.0" range="-1.571 1.571"/>
      <joint name="pelvis_list" type="hinge" axis="1.0 -0.0 0.0" range="-1.571 1.571"/>
      <joint name="pelvis_rotation" type="hinge" axis="0.0 -0.0 1.0" range="-1.571 1.571"/>
      <geom name="pelvis_joint_marker" type="sphere" size="0.015" rgba="1 0 0 1" group="1" contype="0" conaffinity="0"/>
      <geom type="mesh" mesh="sacrum" euler="1.571 0 0" rgba="0.8 0.6 0.4 1" contype="1" conaffinity="1"/>
      <geom type="mesh" mesh="sacrum" euler="1.571 0 0" rgba="0.8 0.6 0.4 1" group="1" contype="0" conaffinity="0"/>
      <geom type="mesh" mesh="pelvis" euler="1.571 0 0" rgba="0.8 0.6 0.4 1" contype="1" conaffinity="1"/>
      <geom type="mesh" mesh="pelvis" euler="1.571 0 0" rgba="0.8 0.6 0.4 1" group="1" contype="0" conaffinity="0"/>
      <geom type="mesh" mesh="l_pelvis" euler="1.571 0 0" rgba="0.8 0.6 0.4 1" contype="1" conaffinity="1"/>
      <geom type="mesh" mesh="l_pelvis" euler="1.571 0 0" rgba="0.8 0.6 0.4 1" group="1" contype="0" conaffinity="0"/>
      <body name="femur_r" pos="-0.0707 -0.0835 -0.0661">
        <inertial pos="0 0 0" mass="9.3014" diaginertia="0.1339 0.0351 0.1412"/>
        <joint name="hip_flexion_r" type="hinge" axis="0.0 -1.0 0.0" range="-2.094 2.094"/>
        <joint name="hip_adduction_r" type="hinge" axis="1.0 -0.0 0.0" range="-2.094 2.094"/>
        <joint name="hip_rotation_r" type="hinge" axis="0.0 -0.0 1.0" range="-2.094 2.094"/>
        <geom name="femur_r_joint_marker" type="sphere" size="0.015" rgba="1 0 0 1" group="1" contype="0" conaffinity="0"/>
        <geom type="mesh" mesh="femur_r" euler="1.571 0 0" rgba="0.8 0.6 0.4 1" contype="1" conaffinity="1"/>
        <geom type="mesh" mesh="femur_r" euler="1.571 0 0" rgba="0.8 0.6 0.4 1" group="1" contype="0" conaffinity="0"/>
        <body name="tibia_r" pos="0.0 -0.0 0.0">
          <inertial pos="0 0 0" mass="3.7075" diaginertia="0.0504 0.0051 0.0511"/>
          <joint name="knee_r_translation1" type="slide" axis="1.0 -0.0 0.0" range="-0.005574 0.00411"/>
          <joint name="knee_r_translation2" type="slide" axis="0.0 -0.0 1.0" range="-0.4226 -0.3953"/>
          <joint name="knee_angle_r" type="hinge" axis="0.0 -1.0 0.0" range="-2.094 0.1745"/>
          <geom name="tibia_r_joint_marker" type="sphere" size="0.015" rgba="1 0 0 1" group="1" contype="0" conaffinity="0"/>
          <geom type="mesh" mesh="tibia_r" euler="1.571 0 0" rgba="0.8 0.6 0.4 1" contype="1" conaffinity="1"/>
          <geom type="mesh" mesh="tibia_r" euler="1.571 0 0" rgba="0.8 0.6 0.4 1" group="1" contype="0" conaffinity="0"/>
          <geom type="mesh" mesh="fibula" euler="1.571 0 0" rgba="0.8 0.6 0.4 1" contype="1" conaffinity="1"/>
          <geom type="mesh" mesh="fibula" euler="1.571 0 0" rgba="0.8 0.6 0.4 1" group="1" contype="0" conaffinity="0"/>
          <body name="talus_r" pos="0.0 -0.0 -0.43">
            <inertial pos="0 0 0" mass="0.1" diaginertia="0.001 0.001 0.001"/>
            <joint name="ankle_angle_r" type="hinge" axis="-0.105 -0.9791 -0.174" range="-1.571 1.571"/>
            <geom name="talus_r_joint_marker" type="sphere" size="0.015" rgba="1 0 0 1" group="1" contype="0" conaffinity="0"/>
            <geom type="mesh" mesh="talus" euler="1.571 0 0" rgba="0.8 0.6 0.4 1" contype="1" conaffinity="1"/>
            <geom type="mesh" mesh="talus" euler="1.571 0 0" rgba="0.8 0.6 0.4 1" group="1" contype="0" conaffinity="0"/>
            <body name="calcn_r" pos="-0.04877 -0.00792 -0.04195">
              <inertial pos="0 0 0" mass="1.25" diaginertia="0.0014 0.0039 0.0041"/>
              <joint name="subtalar_angle_r" type="hinge" axis="0.7872 0.1209 0.6047" range="-1.571 1.571"/>
              <geom name="calcn_r_joint_marker" type="sphere" size="0.015" rgba="1 0 0 1" group="1" contype="0" conaffinity="0"/>
              <geom type="mesh" mesh="foot" euler="1.571 0 0" rgba="0.8 0.6 0.4 1" contype="1" conaffinity="1"/>
              <geom type="mesh" mesh="foot" euler="1.571 0 0" rgba="0.8 0.6 0.4 1" group="1" contype="0" conaffinity="0"/>
              <body name="toes_r" pos="0.1788 -0.00108 -0.002">
                <inertial pos="0 0 0" mass="0.2166" diaginertia="0.0001 0.0002 0.001"/>
                <joint name="mtp_angle_r" type="hinge" axis="-0.581 -0.8139 0.0" range="-1.571 1.571"/>
                <geom name="toes_r_joint_marker" type="sphere" size="0.015" rgba="1 0 0 1" group="1" contype="0" conaffinity="0"/>
                <geom type="mesh" mesh="bofoot" euler="1.571 0 0" rgba="0.8 0.6 0.4 1" contype="1" conaffinity="1"/>
                <geom type="mesh" mesh="bofoot" euler="1.571 0 0" rgba="0.8 0.6 0.4 1" group="1" contype="0" conaffinity="0"/>
              </body>
            </body>
          </body>
          <body name="grac_r_grac_r-P2" pos="0.0 -0.0 0.0">
            <joint name="grac_r_grac_r-P2_x" type="slide" axis="1.0 -0.0 0.0" range="-0.02657 -0.01943"/>
            <joint name="grac_r_grac_r-P2_y" type="slide" axis="0.0 -0.0 1.0" range="-0.05153 -0.0319"/>
            <joint name="grac_r_grac_r-P2_z" type="slide" axis="0.0 -1.0 0.0" range="-0.03774 -0.0358"/>
            <geom name="grac_r_grac_r-P2_joint_marker" type="sphere" size="0.015" rgba="1 0 0 1" group="1" contype="0" conaffinity="0"/>
            <geom type="sphere" size="0.005" rgba="0 0 1 0.5" group="1" contype="0" conaffinity="0"/>
          </body>
          <body name="rect_fem_r_rect_fem_r-P3" pos="0.0 -0.001399 0.0">
            <joint name="rect_fem_r_rect_fem_r-P3_x" type="slide" axis="1.0 -0.0 0.0" range="0.01558 0.0733"/>
            <joint name="rect_fem_r_rect_fem_r-P3_y" type="slide" axis="0.0 -0.0 1.0" range="-0.06738 0.02531"/>
            <geom name="rect_fem_r_rect_fem_r-P3_joint_marker" type="sphere" size="0.015" rgba="1 0 0 1" group="1" contype="0" conaffinity="0"/>
            <geom type="sphere" size="0.005" rgba="0 0 1 0.5" group="1" contype="0" conaffinity="0"/>
          </body>
          <body name="vas_int_r_vas_int_r-P4" pos="0.0 -0.001799 0.0">
            <joint name="vas_int_r_vas_int_r-P4_x" type="slide" axis="1.0 -0.0 0.0" range="0.008273 0.06844"/>
            <joint name="vas_int_r_vas_int_r-P4_y" type="slide" axis="0.0 -0.0 1.0" range="-0.06857 0.02752"/>
            <geom name="vas_int_r_vas_int_r-P4_joint_marker" type="sphere" size="0.015" rgba="1 0 0 1" group="1" contype="0" conaffinity="0"/>
            <geom type="sphere" size="0.005" rgba="0 0 1 0.5" group="1" contype="0" conaffinity="0"/>
          </body>
        </body>
        <body name="vas_int_r_vas_int_r-P3" pos="0.0335 -0.0 0.0">
          <joint name="vas_int_r_vas_int_r-P3_y" type="slide" axis="0.0 -0.0 1.0" range="-0.403 -0.2084"/>
          <joint name="vas_int_r_vas_int_r-P3_z" type="slide" axis="0.0 -1.0 0.0" range="0.0055 0.0285"/>
          <geom name="vas_int_r_vas_int_r-P3_joint_marker" type="sphere" size="0.015" rgba="1 0 0 1" group="1" contype="0" conaffinity="0"/>
          <geom type="sphere" size="0.005" rgba="0 0 1 0.5" group="1" contype="0" conaffinity="0"/>
        </body>
        <body name="med_gas_r_med_gas_r-P2" pos="0.0 -0.0 0.0">
          <joint name="med_gas_r_med_gas_r-P2_x" type="slide" axis="1.0 -0.0 0.0" range="-0.03 -0.019"/>
          <joint name="med_gas_r_med_gas_r-P2_y" type="slide" axis="0.0 -0.0 1.0" range="-0.4022 -0.3929"/>
          <joint name="med_gas_r_med_gas_r-P2_z" type="slide" axis="0.0 -1.0 0.0" range="-0.0258 -0.0235"/>
          <geom name="med_gas_r_med_gas_r-P2_joint_marker" type="sphere" size="0.015" rgba="1 0 0 1" group="1" contype="0" conaffinity="0"/>
          <geom type="sphere" size="0.005" rgba="0 0 1 0.5" group="1" contype="0" conaffinity="0"/>
        </body>
      </body>
      <body name="femur_l" pos="-0.0707 0.0835 -0.0661">
        <inertial pos="0 0 0" mass="9.3014" diaginertia="0.1339 0.0351 0.1412"/>
        <joint name="hip_flexion_l" type="hinge" axis="0.0 -1.0 0.0" range="-2.094 2.094"/>
        <joint name="hip_adduction_l" type="hinge" axis="-1.0 -0.0 0.0" range="-2.094 2.094"/>
        <joint name="hip_rotation_l" type="hinge" axis="0.0 -0.0 -1.0" range="-2.094 2.094"/>
        <geom name="femur_l_joint_marker" type="sphere" size="0.015" rgba="1 0 0 1" group="1" contype="0" conaffinity="0"/>
        <geom type="mesh" mesh="femur_l" euler="1.571 0 0" rgba="0.8 0.6 0.4 1" contype="1" conaffinity="1"/>
        <geom type="mesh" mesh="femur_l" euler="1.571 0 0" rgba="0.8 0.6 0.4 1" group="1" contype="0" conaffinity="0"/>
        <body name="tibia_l" pos="0.0 -0.0 0.0">
          <inertial pos="0 0 0" mass="3.7075" diaginertia="0.0504 0.0051 0.0511"/>
          <joint name="knee_l_translation1" type="slide" axis="1.0 -0.0 0.0" range="-0.005574 0.00411"/>
          <joint name="knee_l_translation2" type="slide" axis="0.0 -0.0 1.0" range="-0.4226 -0.3953"/>
          <joint name="knee_angle_l" type="hinge" axis="0.0 -1.0 0.0" range="-2.094 0.1745"/>
          <geom name="tibia_l_joint_marker" type="sphere" size="0.015" rgba="1 0 0 1" group="1" contype="0" conaffinity="0"/>
          <geom type="mesh" mesh="tibia_l" euler="1.571 0 0" rgba="0.8 0.6 0.4 1" contype="1" conaffinity="1"/>
          <geom type="mesh" mesh="tibia_l" euler="1.571 0 0" rgba="0.8 0.6 0.4 1" group="1" contype="0" conaffinity="0"/>
          <geom type="mesh" mesh="l_fibula" euler="1.571 0 0" rgba="0.8 0.6 0.4 1" contype="1" conaffinity="1"/>
          <geom type="mesh" mesh="l_fibula" euler="1.571 0 0" rgba="0.8 0.6 0.4 1" group="1" contype="0" conaffinity="0"/>
          <body name="talus_l" pos="0.0 -0.0 -0.43">
            <inertial pos="0 0 0" mass="0.1" diaginertia="0.001 0.001 0.001"/>
            <joint name="ankle_angle_l" type="hinge" axis="0.105 -0.9791 0.174" range="-1.571 1.571"/>
            <geom name="talus_l_joint_marker" type="sphere" size="0.015" rgba="1 0 0 1" group="1" contype="0" conaffinity="0"/>
            <geom type="mesh" mesh="l_talus" euler="1.571 0 0" rgba="0.8 0.6 0.4 1" contype="1" conaffinity="1"/>
            <geom type="mesh" mesh="l_talus" euler="1.571 0 0" rgba="0.8 0.6 0.4 1" group="1" contype="0" conaffinity="0"/>
            <body name="calcn_l" pos="-0.04877 0.00792 -0.04195">
              <inertial pos="0 0 0" mass="1.25" diaginertia="0.0014 0.0039 0.0041"/>
              <joint name="subtalar_angle_l" type="hinge" axis="-0.7872 0.1209 -0.6047" range="-1.571 1.571"/>
              <geom name="calcn_l_joint_marker" type="sphere" size="0.015" rgba="1 0 0 1" group="1" contype="0" conaffinity="0"/>
              <geom type="mesh" mesh="l_foot" euler="1.571 0 0" rgba="0.8 0.6 0.4 1" contype="1" conaffinity="1"/>
              <geom type="mesh" mesh="l_foot" euler="1.571 0 0" rgba="0.8 0.6 0.4 1" group="1" contype="0" conaffinity="0"/>
              <body name="toes_l" pos="0.1788 0.00108 -0.002">
                <inertial pos="0 0 0" mass="0.2166" diaginertia="0.0001 0.0002 0.001"/>
                <joint name="mtp_angle_l" type="hinge" axis="0.581 -0.8139 0.0" range="-1.571 1.571"/>
                <geom name="toes_l_joint_marker" type="sphere" size="0.015" rgba="1 0 0 1" group="1" contype="0" conaffinity="0"/>
                <geom type="mesh" mesh="l_bofoot" euler="1.571 0 0" rgba="0.8 0.6 0.4 1" contype="1" conaffinity="1"/>
                <geom type="mesh" mesh="l_bofoot" euler="1.571 0 0" rgba="0.8 0.6 0.4 1" group="1" contype="0" conaffinity="0"/>
              </body>
            </body>
          </body>
          <body name="grac_l_grac_l-P2" pos="0.0 -0.0 0.0">
            <joint name="grac_l_grac_l-P2_x" type="slide" axis="1.0 -0.0 0.0" range="-0.02657 -0.01943"/>
            <joint name="grac_l_grac_l-P2_y" type="slide" axis="0.0 -0.0 1.0" range="-0.05153 -0.0319"/>
            <joint name="grac_l_grac_l-P2_z" type="slide" axis="0.0 -1.0 0.0" range="0.0358 0.03774"/>
            <geom name="grac_l_grac_l-P2_joint_marker" type="sphere" size="0.015" rgba="1 0 0 1" group="1" contype="0" conaffinity="0"/>
            <geom type="sphere" size="0.005" rgba="0 0 1 0.5" group="1" contype="0" conaffinity="0"/>
          </body>
          <body name="rect_fem_l_rect_fem_l-P3" pos="0.0 0.001401 0.0">
            <joint name="rect_fem_l_rect_fem_l-P3_x" type="slide" axis="1.0 -0.0 0.0" range="0.01558 0.0733"/>
            <joint name="rect_fem_l_rect_fem_l-P3_y" type="slide" axis="0.0 -0.0 1.0" range="-0.06738 0.02531"/>
            <geom name="rect_fem_l_rect_fem_l-P3_joint_marker" type="sphere" size="0.015" rgba="1 0 0 1" group="1" contype="0" conaffinity="0"/>
            <geom type="sphere" size="0.005" rgba="0 0 1 0.5" group="1" contype="0" conaffinity="0"/>
          </body>
          <body name="vas_int_l_vas_int_l-P4" pos="0.0 0.001801 0.0">
            <joint name="vas_int_l_vas_int_l-P4_x" type="slide" axis="1.0 -0.0 0.0" range="0.008273 0.06844"/>
            <joint name="vas_int_l_vas_int_l-P4_y" type="slide" axis="0.0 -0.0 1.0" range="-0.06857 0.02752"/>
            <geom name="vas_int_l_vas_int_l-P4_joint_marker" type="sphere" size="0.015" rgba="1 0 0 1" group="1" contype="0" conaffinity="0"/>
            <geom type="sphere" size="0.005" rgba="0 0 1 0.5" group="1" contype="0" conaffinity="0"/>
          </body>
        </body>
        <body name="vas_int_l_vas_int_l-P3" pos="0.0335 -0.0 0.0">
          <joint name="vas_int_l_vas_int_l-P3_y" type="slide" axis="0.0 -0.0 1.0" range="-0.403 -0.2084"/>
          <joint name="vas_int_l_vas_int_l-P3_z" type="slide" axis="0.0 -1.0 0.0" range="-0.0285 -0.0055"/>
          <geom name="vas_int_l_vas_int_l-P3_joint_marker" type="sphere" size="0.015" rgba="1 0 0 1" group="1" contype="0" conaffinity="0"/>
          <geom type="sphere" size="0.005" rgba="0 0 1 0.5" group="1" contype="0" conaffinity="0"/>
        </body>
        <body name="med_gas_l_med_gas_l-P2" pos="0.0 -0.0 0.0">
          <joint name="med_gas_l_med_gas_l-P2_x" type="slide" axis="1.0 -0.0 0.0" range="-0.03 -0.019"/>
          <joint name="med_gas_l_med_gas_l-P2_y" type="slide" axis="0.0 -0.0 1.0" range="-0.4022 -0.3929"/>
          <joint name="med_gas_l_med_gas_l-P2_z" type="slide" axis="0.0 -1.0 0.0" range="0.0235 0.0258"/>
          <geom name="med_gas_l_med_gas_l-P2_joint_marker" type="sphere" size="0.015" rgba="1 0 0 1" group="1" contype="0" conaffinity="0"/>
          <geom type="sphere" size="0.005" rgba="0 0 1 0.5" group="1" contype="0" conaffinity="0"/>
        </body>
      </body>
      <body name="torso" pos="-0.1007 -0.0 0.0815">
        <inertial pos="0 0 0" mass="34.2366" diaginertia="1.4745 0.7555 1.4314"/>
        <joint name="lumbar_extension" type="hinge" axis="0.0 -1.0 0.0" range="-1.571 1.571"/>
        <joint name="lumbar_bending" type="hinge" axis="1.0 -0.0 0.0" range="-1.571 1.571"/>
        <joint name="lumbar_rotation" type="hinge" axis="0.0 -0.0 1.0" range="-1.571 1.571"/>
        <geom name="torso_joint_marker" type="sphere" size="0.015" rgba="1 0 0 1" group="1" contype="0" conaffinity="0"/>
        <geom type="mesh" mesh="hat_spine" euler="1.571 0 0" rgba="0.8 0.6 0.4 1" contype="1" conaffinity="1"/>
        <geom type="mesh" mesh="hat_spine" euler="1.571 0 0" rgba="0.8 0.6 0.4 1" group="1" contype="0" conaffinity="0"/>
        <geom type="mesh" mesh="hat_jaw" euler="1.571 0 0" rgba="0.8 0.6 0.4 1" contype="1" conaffinity="1"/>
        <geom type="mesh" mesh="hat_jaw" euler="1.571 0 0" rgba="0.8 0.6 0.4 1" group="1" contype="0" conaffinity="0"/>
        <geom type="mesh" mesh="hat_skull" euler="1.571 0 0" rgba="0.8 0.6 0.4 1" contype="1" conaffinity="1"/>
        <geom type="mesh" mesh="hat_skull" euler="1.571 0 0" rgba="0.8 0.6 0.4 1" group="1" contype="0" conaffinity="0"/>
        <geom type="mesh" mesh="hat_ribs" euler="1.571 0 0" rgba="0.8 0.6 0.4 1" contype="1" conaffinity="1"/>
        <geom type="mesh" mesh="hat_ribs" euler="1.571 0 0" rgba="0.8 0.6 0.4 1" group="1" contype="0" conaffinity="0"/>
      </body>
      <body name="iliacus_r_iliacus_r-P3" pos="0.0 -0.0811 0.0">
        <joint name="iliacus_r_iliacus_r-P3_x" type="slide" axis="1.0 -0.0 0.0" range="-0.0288 -0.0258"/>
        <joint name="iliacus_r_iliacus_r-P3_y" type="slide" axis="0.0 -0.0 1.0" range="-0.0805 -0.055"/>
        <geom name="iliacus_r_iliacus_r-P3_joint_marker" type="sphere" size="0.015" rgba="1 0 0 1" group="1" contype="0" conaffinity="0"/>
        <geom type="sphere" size="0.005" rgba="0 0 1 0.5" group="1" contype="0" conaffinity="0"/>
      </body>
      <body name="psoas_r_psoas_r-P3" pos="0.0 -0.0 0.0">
        <joint name="psoas_r_psoas_r-P3_x" type="slide" axis="1.0 -0.0 0.0" range="-0.0288 -0.0238"/>
        <joint name="psoas_r_psoas_r-P3_y" type="slide" axis="0.0 -0.0 1.0" range="-0.0805 -0.057"/>
        <joint name="psoas_r_psoas_r-P3_z" type="slide" axis="0.0 -1.0 0.0" range="0.0759 0.0816"/>
        <geom name="psoas_r_psoas_r-P3_joint_marker" type="sphere" size="0.015" rgba="1 0 0 1" group="1" contype="0" conaffinity="0"/>
        <geom type="sphere" size="0.005" rgba="0 0 1 0.5" group="1" contype="0" conaffinity="0"/>
      </body>
      <body name="iliacus_l_iliacus_l-P3" pos="0.0 0.0816 0.0">
        <joint name="iliacus_l_iliacus_l-P3_x" type="slide" axis="1.0 -0.0 0.0" range="-0.0288 -0.0258"/>
        <joint name="iliacus_l_iliacus_l-P3_y" type="slide" axis="0.0 -0.0 1.0" range="-0.0805 -0.055"/>
        <geom name="iliacus_l_iliacus_l-P3_joint_marker" type="sphere" size="0.015" rgba="1 0 0 1" group="1" contype="0" conaffinity="0"/>
        <geom type="sphere" size="0.005" rgba="0 0 1 0.5" group="1" contype="0" conaffinity="0"/>
      </body>
      <body name="psoas_l_psoas_l-P3" pos="0.0 -0.0 0.0">
        <joint name="psoas_l_psoas_l-P3_x" type="slide" axis="1.0 -0.0 0.0" range="-0.0288 -0.0238"/>
        <joint name="psoas_l_psoas_l-P3_y" type="slide" axis="0.0 -0.0 1.0" range="-0.0805 -0.057"/>
        <joint name="psoas_l_psoas_l-P3_z" type="slide" axis="0.0 -1.0 0.0" range="-0.0816 -0.0759"/>
        <geom name="psoas_l_psoas_l-P3_joint_marker" type="sphere" size="0.015" rgba="1 0 0 1" group="1" contype="0" conaffinity="0"/>
        <geom type="sphere" size="0.005" rgba="0 0 1 0.5" group="1" contype="0" conaffinity="0"/>
      </body>
    </body>
  </worldbody>
  <contact>
    <exclude body1="pelvis" body2="femur_r"/>
    <exclude body1="femur_r" body2="tibia_r"/>
    <exclude body1="tibia_r" body2="talus_r"/>
    <exclude body1="talus_r" body2="calcn_r"/>
    <exclude body1="calcn_r" body2="toes_r"/>
    <exclude body1="tibia_r" body2="grac_r_grac_r-P2"/>
    <exclude body1="tibia_r" body2="rect_fem_r_rect_fem_r-P3"/>
    <exclude body1="tibia_r" body2="vas_int_r_vas_int_r-P4"/>
    <exclude body1="femur_r" body2="vas_int_r_vas_int_r-P3"/>
    <exclude body1="femur_r" body2="med_gas_r_med_gas_r-P2"/>
    <exclude body1="pelvis" body2="femur_l"/>
    <exclude body1="femur_l" body2="tibia_l"/>
    <exclude body1="tibia_l" body2="talus_l"/>
    <exclude body1="talus_l" body2="calcn_l"/>
    <exclude body1="calcn_l" body2="toes_l"/>
    <exclude body1="tibia_l" body2="grac_l_grac_l-P2"/>
    <exclude body1="tibia_l" body2="rect_fem_l_rect_fem_l-P3"/>
    <exclude body1="tibia_l" body2="vas_int_l_vas_int_l-P4"/>
    <exclude body1="femur_l" body2="vas_int_l_vas_int_l-P3"/>
    <exclude body1="femur_l" body2="med_gas_l_med_gas_l-P2"/>
    <exclude body1="pelvis" body2="torso"/>
    <exclude body1="pelvis" body2="iliacus_r_iliacus_r-P3"/>
    <exclude body1="pelvis" body2="psoas_r_psoas_r-P3"/>
    <exclude body1="pelvis" body2="iliacus_l_iliacus_l-P3"/>
    <exclude body1="pelvis" body2="psoas_l_psoas_l-P3"/>
  </contact>
</mujoco>
