<?xml version="1.0" ?>
<mujoco model="gait2354_simplified">
  <compiler angle="radian" coordinate="local" inertiafromgeom="auto"/>
  
  <default>
    <joint limited="true" damping="5.0" armature="0.01" stiffness="0"/>
    <geom conaffinity="1" condim="3" contype="1" margin="0.001" rgba="0.8 0.6 0.4 1" density="1000"/>
  </default>
  
  <asset>
    <texture type="skybox" builtin="gradient" rgb1=".4 .5 .6" rgb2="0 0 0" width="100" height="100"/>
    <texture builtin="flat" height="1278" mark="cross" markrgb="1 1 1" name="texgeom" random="0.01" rgb1="0.8 0.6 0.4" rgb2="0.8 0.6 0.4" type="cube" width="127"/>
    <texture builtin="checker" height="100" name="texplane" rgb1="0 0 0" rgb2="0.8 0.8 0.8" type="2d" width="100"/>
    <material name="MatPlane" reflectance="0.5" shininess="1" specular="1" texrepeat="60 60" texture="texplane"/>
    <material name="geom" texture="texgeom" texuniform="true"/>
  </asset>
  
  <worldbody>
    <light cutoff="100" diffuse="1 1 1" dir="0 0 -1.3" directional="true" exponent="1" pos="0 0 1.3" specular=".1 .1 .1"/>
    <geom name="floor" type="plane" conaffinity="1" size="100 100 .2" material="MatPlane"/>
    
    <body name="pelvis" pos="0 0 0.95">
      <freejoint name="root"/>
      <inertial pos="0 0 0" mass="11.777" diaginertia="0.1028 0.0871 0.0579"/>
      <geom name="pelvis_geom" type="box" size="0.083 0.107 0.072" rgba="0.8 0.6 0.4 1"/>
      
      <!-- Right Leg -->
      <body name="femur_r" pos="-0.0707 -0.0835 -0.0661">
        <inertial pos="0 0 -0.17" mass="9.3014" diaginertia="0.1339 0.0351 0.1412"/>
        <joint name="hip_flexion_r" type="hinge" pos="0 0 0" axis="0 1 0" range="-2.094 2.094" stiffness="800" damping="80" armature="0.02"/>
        <joint name="hip_adduction_r" type="hinge" pos="0 0 0" axis="1 0 0" range="-2.094 2.094" stiffness="800" damping="80" armature="0.02"/>
        <joint name="hip_rotation_r" type="hinge" pos="0 0 0" axis="0 0 1" range="-2.094 2.094" stiffness="800" damping="80" armature="0.02"/>
        <geom name="femur_r_geom" type="capsule" fromto="0 0 0 0 0 -0.395" size="0.06" rgba="0.8 0.6 0.4 1"/>
        
        <body name="tibia_r" pos="0 0 -0.395">
          <inertial pos="0 0 -0.215" mass="3.7075" diaginertia="0.0504 0.0051 0.0511"/>
          <joint name="knee_angle_r" type="hinge" pos="0 0 0" axis="0 1 0" range="-2.094 0.1745" stiffness="800" damping="80" armature="0.02"/>
          <geom name="tibia_r_geom" type="capsule" fromto="0 0 0 0 0 -0.43" size="0.054" rgba="0.8 0.6 0.4 1"/>
          
          <body name="talus_r" pos="0 0 -0.43">
            <inertial pos="0 0 0" mass="0.1" diaginertia="0.001 0.001 0.001"/>
            <joint name="ankle_angle_r" type="hinge" pos="0 0 0" axis="0 1 0" range="-1.571 1.571" stiffness="800" damping="80" armature="0.02"/>
            
            <body name="calcn_r" pos="0 0 -0.045">
              <inertial pos="0.05 0 0" mass="1.25" diaginertia="0.0014 0.0039 0.0041"/>
              <geom name="calcn_r_geom" type="capsule" fromto="-0.02 0 0 0.1 0 -0.03" size="0.03" rgba="0.8 0.6 0.4 1"/>
              
              <body name="toes_r" pos="0.1793 0 -0.0282">
                <inertial pos="0.035 0 0" mass="0.2166" diaginertia="0.0001 0.0003 0.0003"/>
                <joint name="mtp_angle_r" type="hinge" pos="0 0 0" axis="0 1 0" range="-1.571 1.571" stiffness="500" damping="50" armature="0.02"/>
                <geom name="toes_r_geom" type="box" size="0.05 0.025 0.015" pos="0.035 0 0" rgba="0.8 0.6 0.4 1"/>
              </body>
            </body>
          </body>
        </body>
      </body>
      
      <!-- Left Leg -->
      <body name="femur_l" pos="-0.0707 0.0835 -0.0661">
        <inertial pos="0 0 -0.17" mass="9.3014" diaginertia="0.1339 0.0351 0.1412"/>
        <joint name="hip_flexion_l" type="hinge" pos="0 0 0" axis="0 1 0" range="-2.094 2.094" stiffness="800" damping="80" armature="0.02"/>
        <joint name="hip_adduction_l" type="hinge" pos="0 0 0" axis="-1 0 0" range="-2.094 2.094" stiffness="800" damping="80" armature="0.02"/>
        <joint name="hip_rotation_l" type="hinge" pos="0 0 0" axis="0 0 -1" range="-2.094 2.094" stiffness="800" damping="80" armature="0.02"/>
        <geom name="femur_l_geom" type="capsule" fromto="0 0 0 0 0 -0.395" size="0.06" rgba="0.8 0.6 0.4 1"/>
        
        <body name="tibia_l" pos="0 0 -0.395">
          <inertial pos="0 0 -0.215" mass="3.7075" diaginertia="0.0504 0.0051 0.0511"/>
          <joint name="knee_angle_l" type="hinge" pos="0 0 0" axis="0 1 0" range="-2.094 0.1745" stiffness="800" damping="80" armature="0.02"/>
          <geom name="tibia_l_geom" type="capsule" fromto="0 0 0 0 0 -0.43" size="0.054" rgba="0.8 0.6 0.4 1"/>
          
          <body name="talus_l" pos="0 0 -0.43">
            <inertial pos="0 0 0" mass="0.1" diaginertia="0.001 0.001 0.001"/>
            <joint name="ankle_angle_l" type="hinge" pos="0 0 0" axis="0 1 0" range="-1.571 1.571" stiffness="800" damping="80" armature="0.02"/>
            
            <body name="calcn_l" pos="0 0 -0.045">
              <inertial pos="0.05 0 0" mass="1.25" diaginertia="0.0014 0.0039 0.0041"/>
              <geom name="calcn_l_geom" type="capsule" fromto="-0.02 0 0 0.1 0 -0.03" size="0.03" rgba="0.8 0.6 0.4 1"/>
              
              <body name="toes_l" pos="0.1793 0 -0.0282">
                <inertial pos="0.035 0 0" mass="0.2166" diaginertia="0.0001 0.0003 0.0003"/>
                <joint name="mtp_angle_l" type="hinge" pos="0 0 0" axis="0 1 0" range="-1.571 1.571" stiffness="500" damping="50" armature="0.02"/>
                <geom name="toes_l_geom" type="box" size="0.05 0.025 0.015" pos="0.035 0 0" rgba="0.8 0.6 0.4 1"/>
              </body>
            </body>
          </body>
        </body>
      </body>
      
      <!-- Torso -->
      <body name="torso" pos="-0.1007 0 0.0815">
        <inertial pos="0 0 0.2" mass="34.2366" diaginertia="1.4745 0.7555 1.4314"/>
        <joint name="lumbar_extension" type="hinge" pos="0 0 0" axis="0 1 0" range="-1.571 1.571" stiffness="1000" damping="100" armature="0.02"/>
        <joint name="lumbar_bending" type="hinge" pos="0 0 0" axis="1 0 0" range="-1.571 1.571" stiffness="1000" damping="100" armature="0.02"/>
        <joint name="lumbar_rotation" type="hinge" pos="0 0 0" axis="0 0 1" range="-1.571 1.571" stiffness="1000" damping="100" armature="0.02"/>
        <geom name="torso_geom" type="capsule" fromto="0 0 0 0 0 0.4" size="0.1" rgba="0.8 0.6 0.4 1"/>
      </body>
    </body>
  </worldbody>
  
  <contact>
    <exclude body1="pelvis" body2="femur_r"/>
    <exclude body1="femur_r" body2="tibia_r"/>
    <exclude body1="tibia_r" body2="talus_r"/>
    <exclude body1="talus_r" body2="calcn_r"/>
    <exclude body1="calcn_r" body2="toes_r"/>
    <exclude body1="pelvis" body2="femur_l"/>
    <exclude body1="femur_l" body2="tibia_l"/>
    <exclude body1="tibia_l" body2="talus_l"/>
    <exclude body1="talus_l" body2="calcn_l"/>
    <exclude body1="calcn_l" body2="toes_l"/>
    <exclude body1="pelvis" body2="torso"/>
  </contact>
</mujoco>
