<mujoco model="humanoid">
  <compiler coordinate="local"/>
  <default>
    <joint damping="0.0" armature="0.01" stiffness="0.0" limited="true"/>
    <geom conaffinity="1" condim="3" contype="7" margin="0.001" rgba="0.8 0.6 .4 1"/>
  </default>
  <asset>
    <texture type="skybox" builtin="gradient" rgb1=".4 .5 .6" rgb2="0 0 0" width="100" height="100"/>
    <texture builtin="flat" height="1278" mark="cross" markrgb="1 1 1" name="texgeom" random="0.01" rgb1="0.8 0.6 0.4" rgb2="0.8 0.6 0.4" type="cube" width="127"/>
    <texture builtin="checker" height="100" name="texplane" rgb1="0 0 0" rgb2="0.8 0.8 0.8" type="2d" width="100"/>
    <material name="MatPlane" reflectance="0.5" shininess="1" specular="1" texrepeat="60 60" texture="texplane"/>
    <material name="geom" texture="texgeom" texuniform="true"/>
  </asset>
  <worldbody>
    <light cutoff="100" diffuse="1 1 1" dir="-0 0 -1.3" directional="true" exponent="1" pos="0 0 1.3" specular=".1 .1 .1"/>
    <body name="Pelvis" pos="-0.0018 -0.2233 0.0282">
      <freejoint name="Pelvis"/>
      <geom type="box" pos="-0.0055 -0.0000 -0.0121" size="0.083 0.140 0.0722" quat="1.0000 0.0000 0.0000 0.0000" density="1000"/>
      <body name="L_Hip" pos="-0.0066 0.0950 -0.0910">
        <joint name="L_Hip_x" type="hinge" pos="0 0 0" axis="1 0 0" stiffness="250" damping="25" armature="0.02" range="-20.0000 45.0000"/>
        <joint name="L_Hip_y" type="hinge" pos="0 0 0" axis="0 1 0" stiffness="250" damping="25" armature="0.02" range="-30.0000 120.0000"/>
        <joint name="L_Hip_z" type="hinge" pos="0 0 0" axis="0 0 1" stiffness="250" damping="25" armature="0.02" range="-45.0000 45.0000"/>
        <geom type="capsule" contype="1" conaffinity="1" density="2040.816327" fromto="0.0000 0.0000 -0.0750 0.0000 0.0000 -0.3039" size="0.0606"/>
        <body name="L_Knee" pos="-0.0067 0.0000 -0.3789">
          <joint name="L_Knee_x" type="hinge" pos="0 0 0" axis="1 0 0" stiffness="200" damping="20" armature="0.02" range="-10.0000 10.0000"/>
          <joint name="L_Knee_y" type="hinge" pos="0 0 0" axis="0 1 0" stiffness="200" damping="20" armature="0.02" range="-10.0000 150.0000"/>
          <joint name="L_Knee_z" type="hinge" pos="0 0 0" axis="0 0 1" stiffness="200" damping="20" armature="0.02" range="-15.0000 15.0000"/>
          <geom type="capsule" contype="1" conaffinity="1" density="1234.567901" fromto="0.0000 0.0000 -0.0797 0.0000 0.0000 -0.3185" size="0.0541"/>
          <body name="L_Ankle" pos="0.0000 0.0000 -0.3982">
            <joint name="L_Ankle_x" type="hinge" pos="0 0 0" axis="1 0 0" stiffness="150" damping="15" armature="0.02" range="-10.0000 10.0000"/>
            <joint name="L_Ankle_y" type="hinge" pos="0 0 0" axis="0 1 0" stiffness="150" damping="15" armature="0.02" range="-45.0000 20.0000"/>
            <joint name="L_Ankle_z" type="hinge" pos="0 0 0" axis="0 0 1" stiffness="150" damping="15" armature="0.02" range="-10.0000 10.0000"/>
            <geom type="box" pos="0.0225 0.0 -0.0200" size="0.0865 0.04 0.0478" quat="1.0000 0.0000 0.0000 0.0000" density="1000"/>
            <body name="L_Toe" pos="0.1233 0.0000 -0.0550">
              <joint name="L_Toe_x" type="hinge" pos="0 0 0" axis="1 0 0" stiffness="75" damping="8" armature="0.02" range="-10.0000 10.0000"/>
              <joint name="L_Toe_y" type="hinge" pos="0 0 0" axis="0 1 0" stiffness="75" damping="8" armature="0.02" range="-20.0000 20.0000"/>
              <joint name="L_Toe_z" type="hinge" pos="0 0 0" axis="0 0 1" stiffness="75" damping="8" armature="0.02" range="-5.0000 5.0000"/>
              <geom type="box" pos="0.0248 0.0 0.007" size="0.0496 0.04 0.02" quat="1.0000 0.0000 0.0000 0.0000" density="1000"/>
            </body>
          </body>
        </body>
      </body>
      <body name="R_Hip" pos="-0.0066 -0.0950 -0.0910">
        <joint name="R_Hip_x" type="hinge" pos="0 0 0" axis="1 0 0" stiffness="250" damping="25" armature="0.02" range="-20.0000 45.0000"/>
        <joint name="R_Hip_y" type="hinge" pos="0 0 0" axis="0 1 0" stiffness="250" damping="25" armature="0.02" range="-30.0000 120.0000"/>
        <joint name="R_Hip_z" type="hinge" pos="0 0 0" axis="0 0 1" stiffness="250" damping="25" armature="0.02" range="-15.0000 15.0000"/>
        <geom type="capsule" contype="1" conaffinity="1" density="2040.816327" fromto="0.0000 0.0000 -0.0750 0.0000 0.0000 -0.3039" size="0.0606"/>
        <body name="R_Knee" pos="-0.0067 0.0000 -0.3789">
          <joint name="R_Knee_x" type="hinge" pos="0 0 0" axis="1 0 0" stiffness="200" damping="20" armature="0.02" range="-10.0000 10.0000"/>
          <joint name="R_Knee_y" type="hinge" pos="0 0 0" axis="0 1 0" stiffness="200" damping="20" armature="0.02" range="-10.0000 150.0000"/>
          <joint name="R_Knee_z" type="hinge" pos="0 0 0" axis="0 0 1" stiffness="200" damping="20" armature="0.02" range="-15.0000 15.0000"/>
          <geom type="capsule" contype="1" conaffinity="1" density="1234.567901" fromto="0.0000 0.0000 -0.0797 0.0000 0.0000 -0.3185" size="0.0541"/>
          <body name="R_Ankle" pos="0.0000 0.0000 -0.3982">
            <joint name="R_Ankle_x" type="hinge" pos="0 0 0" axis="1 0 0" stiffness="150" damping="15" armature="0.02" range="-25.0000 25.0000"/>
            <joint name="R_Ankle_y" type="hinge" pos="0 0 0" axis="0 1 0" stiffness="150" damping="15" armature="0.02" range="-45.0000 20.0000"/>
            <joint name="R_Ankle_z" type="hinge" pos="0 0 0" axis="0 0 1" stiffness="150" damping="15" armature="0.02" range="-10.0000 10.0000"/>
            <geom type="box" pos="0.0225 0.0 -0.0200" size="0.0865 0.04 0.0478" quat="1.0000 0.0000 0.0000 0.0000" density="1000"/>
            <body name="R_Toe" pos="0.1233 0.0000 -0.0550">
              <joint name="R_Toe_x" type="hinge" pos="0 0 0" axis="1 0 0" stiffness="75" damping="8" armature="0.02" range="-10.0000 10.0000"/>
              <joint name="R_Toe_y" type="hinge" pos="0 0 0" axis="0 1 0" stiffness="75" damping="8" armature="0.02" range="-20.0000 20.0000"/>
              <joint name="R_Toe_z" type="hinge" pos="0 0 0" axis="0 0 1" stiffness="75" damping="8" armature="0.02" range="-5.0000 5.0000"/>
              <geom type="box" pos="0.0248 0.0 0.007" size="0.0496 0.04 0.02" quat="1.0000 0.0000 0.0000 0.0000" density="1000"/>
            </body>
          </body>
        </body>
      </body>
    </body>
  </worldbody>
  <actuator>
    <motor name="L_Hip_x" joint="L_Hip_x" gear="500"/>
    <motor name="L_Hip_y" joint="L_Hip_y" gear="500"/>
    <motor name="L_Hip_z" joint="L_Hip_z" gear="500"/>
    <motor name="L_Knee_x" joint="L_Knee_x" gear="500"/>
    <motor name="L_Knee_y" joint="L_Knee_y" gear="500"/>
    <motor name="L_Knee_z" joint="L_Knee_z" gear="500"/>
    <motor name="L_Ankle_x" joint="L_Ankle_x" gear="500"/>
    <motor name="L_Ankle_y" joint="L_Ankle_y" gear="500"/>
    <motor name="L_Ankle_z" joint="L_Ankle_z" gear="500"/>
    <motor name="L_Toe_x" joint="L_Toe_x" gear="500"/>
    <motor name="L_Toe_y" joint="L_Toe_y" gear="500"/>
    <motor name="L_Toe_z" joint="L_Toe_z" gear="500"/>
    <motor name="R_Hip_x" joint="R_Hip_x" gear="500"/>
    <motor name="R_Hip_y" joint="R_Hip_y" gear="500"/>
    <motor name="R_Hip_z" joint="R_Hip_z" gear="500"/>
    <motor name="R_Knee_x" joint="R_Knee_x" gear="500"/>
    <motor name="R_Knee_y" joint="R_Knee_y" gear="500"/>
    <motor name="R_Knee_z" joint="R_Knee_z" gear="500"/>
    <motor name="R_Ankle_x" joint="R_Ankle_x" gear="500"/>
    <motor name="R_Ankle_y" joint="R_Ankle_y" gear="500"/>
    <motor name="R_Ankle_z" joint="R_Ankle_z" gear="500"/>
    <motor name="R_Toe_x" joint="R_Toe_x" gear="500"/>
    <motor name="R_Toe_y" joint="R_Toe_y" gear="500"/>
    <motor name="R_Toe_z" joint="R_Toe_z" gear="500"/>
  </actuator>
</mujoco>